Workbook

Sheet 00_LEEME
A1: Anexo E · Matrices auditables del MVP Marley Coffee HORECA
A2: Versión1.9 ·19-10-2026 · Modelo confirmado: comodato y compra mensual de insumos. Recorrido: Productos C10 → Máquinas C11 → Contacto C03 → Diagnóstico C04. El test15oct corresponde a la versión anterior; no valida estas mejoras.
A4: Hoja | B4: Contenido
A5: 01_ENGAGEMENT | B5: Engagement Score v1.1: 13 eventos M2 + evento 14 (comuna). Calculadora con 3 casos; cambia las celdas amarillas.
A6: 02_ZONAS | B6: Comunas, prioridad geográfica (A, B, C, regiones), puntos, potencial, ejecutiva de zona (ficticia) y ruta (demo).
A7: 03_FINANCIAL | B7: Financial Score v0.1 con pesos editables y cálculo para 20 cuentas ficticias; compara con el valor del prototipo.
A8: 04_KPIS | B8: KPIs comerciales, operacionales, de inbound y de experiencia: fórmula, unidad, ventana, fuente, frecuencia, responsable y umbral.
A9: 05_WORKFLOWS | B9: Workflows de inbound automatizado: gatillador, condición, espera, canal, contenido, supresión y KPI.
A10: 06_CONTENIDOS | B10: Piezas audiovisuales y gráficas por etapa del funnel y segmento, con estado.
A11: 07_TEST_PLAN | B11: Plan de test de usabilidad: tareas críticas, criterio de éxito, métricas y umbrales; cuáles se midieron en la ronda 1 (15-10).
A12: 08_TEST_REGISTRO | B12: Registro real de la ronda 1 (P1 a P5, 15-10-2026) y filas para la ronda 2. El resumen por tarea se calcula solo.
A13: 09_SUS | B13: SUS por participante en la ronda 1 (puntaje registrado por el test) y cuestionario de 10 ítems con su fórmula para la ronda 2.
A14: 10_HALLAZGOS | B14: Hallazgos con frecuencia, impacto, severidad (0–4) y mejora. Ciclo 0 = revisión interna (09 a 12-10); ciclo 1 = test con 5 usuarios (15-10).
A15: 11_COMPARACION | B15: Comparación v3 → v4 → v5 (métricas de diseño verificadas), resultados de la ronda 1 contra umbrales y cambios v5 → v6 después del test.
... A29: Convención | B29: Celdas amarillas = datos que se ingresan. Celdas grises = fórmulas. Participantes del test con código (P1 a P5), sin nombres. Datos de clientes, montos y nombres de ejecutivas: ficticios de demostración.

Sheet 01_ENGAGEMENT
A1: Engagement Score v1.1 · prospectos
A2: 13 eventos y pesos de la tabla M2 (informe MVP corregido, fuente [3]) + evento 14 «comuna» (ajuste 10-10). Cada evento suma una vez; tope 100.
A4: N° | B4: Clave | C4: Evento | D4: Puntos | E4: Regla / control | F4: Caso A (1 = ocurrió) | G4: Caso B (1 = ocurrió) | H4: Caso C (1 = ocurrió) | J4: Desde | K4: Banda | L4: Acción típica
A5: 1 | B5: cotizar | C5: Pulsa «Encontrar mi solución» | D5: 10 | E5: Una vez por contacto. | F5: 1 | G5: 1 | H5: 1 | J5: 0 | K5: Exploración | L5: Contenido y nutrición suave
A6: 2 | B6: form1 | C6: Deja su correo con permiso (formulario 1) | D6: 20 | E6: Solo con correo válido y permiso. | F6: 1 | G6: 1 | H6: 1 | J6: 20 | K6: Identificado | L6: Continuidad automática
A7: 3 | B7: portal | C7: Entra a su portal | D7: 8 | E7: Primera entrada al portal. | F7: 1 | G7: 1 | H7: 1 | J7: 40 | K7: Calificado | L7: Recomendación y seguimiento
A8: 4 | B8: diag_inicio | C8: Inicia el diagnóstico | D8: 5 | E8: Primera respuesta. | F8: 1 | G8: 1 | H8: 1 | J8: 60 | K8: Alta intención | L8: Prioridad comercial
A9: 5 | B9: negocio | C9: Tipo de negocio | D9: 4 | E9: Define fit HORECA. | F9: 1 | G9: 1 | H9: 1 | J9: 80 | K9: Prioridad máxima | L9: Persona del equipo ahora
A10: 6 | B10: volumen | C10: Volumen de tazas | D10: 5 | E10: «No lo sé» cuenta. | F10: 1 | G10: 1 | H10: 1
A11: 7 | B11: operacion | C11: Forma de servicio | D11: 4 | E11: Define formato. | F11: 1 | G11: 1 | H11: 1
A12: 8 | B12: preferencias | C12: Qué quiere ofrecer | D12: 4 | E12: Una vez aunque elija varias. | F12: 1 | G12: 1 | H12: 1
A13: 9 | B13: canal | C13: Confirma correo de contacto | D13: 3 | E13: Correo para seguimiento comercial. | F13: 1 | G13: 1 | H13: 1
A14: 10 | B14: recomendacion | C14: Revisa su recomendación | D14: 8 | E14: Portal con diagnóstico completo. | F14: 1 | G14: 1 | H14: 1
A15: 11 | B15: propuesta | C15: Acepta la propuesta | D15: 15 | E15: Señal comercial para SQL. | F15: 0 | G15: 0 | H15: 0
A16: 12 | B16: ejecutivo | C16: Pide hablar con una persona | D16: 12 | E16: Al elegir cualquier canal humano. | F16: 1 | G16: 1 | H16: 1
A17: 13 | B17: expansion | C17: Elige la propuesta ampliada | D17: 12 | E17: Elige ampliada. | F17: 0 | G17: 0 | H17: 0
A18: 14 | B18: comuna | C18: Comuna del local (evento 14) | D18: según zona | E18: Puntos desde 02_ZONAS. | F18: Las Condes | G18: Santiago Centro | H18: Maipú
C20: Suma eventos M2 | F20: =SUMPRODUCT($D$5:$D$17,F5:F17) | G20: =SUMPRODUCT($D$5:$D$17,G5:G17) | H20: =SUMPRODUCT($D$5:$D$17,H5:H17)
C21: Puntos por comuna | F21: =VLOOKUP(F18,'02_ZONAS'!$A$5:$D$31,4,FALSE) | G21: =VLOOKUP(G18,'02_ZONAS'!$A$5:$D$31,4,FALSE) | H21: =VLOOKUP(H18,'02_ZONAS'!$A$5:$D$31,4,FALSE)
C22: Puntaje (tope 100) | F22: =MIN(100,F20+F21) | G22: =MIN(100,G20+G21) | H22: =MIN(100,H20+H21)
C23: Banda | F23: =VLOOKUP(F22,$J$5:$K$9,2,TRUE) | G23: =VLOOKUP(G22,$J$5:$K$9,2,TRUE) | H23: =VLOOKUP(H22,$J$5:$K$9,2,TRUE)
C24: Negocio HORECA (Sí/No) | F24: Sí | G24: Sí | H24: Sí
C25: ¿MQL? (permiso + HORECA + ≥ 40) | F25: =IF(AND(F6=1,F24="Sí",F22>=40),"Sí","No") | G25: =IF(AND(G6=1,G24="Sí",G22>=40),"Sí","No") | H25: =IF(AND(H6=1,H24="Sí",H22>=40),"Sí","No")
C26: ¿Candidato a SQL? (MQL + pidió persona o propuesta) | F26: =IF(AND(F25="Sí",OR(F16=1,F15=1)),"Sí, lo acepta una persona","No") | G26: =IF(AND(G25="Sí",OR(G16=1,G15=1)),"Sí, lo acepta una persona","No") | H26: =IF(AND(H25="Sí",OR(H16=1,H15=1)),"Sí, lo acepta una persona","No")
C28: Lectura: con el mismo recorrido, el puntaje cambia solo por la comuna (A +10, B +6, C +3). Verificado en el prototipo el 10-10: 93, 89 y 86.

Sheet 02_ZONAS
A1: Prioridad geográfica por comuna
A2: Hipótesis del equipo a calibrar con ventas reales por comuna. Ejecutivas con nombres ficticios. Rutas de demostración.
A4: Comuna | B4: Zona | C4: Prioridad | D4: Puntos Engagement | E4: Potencial Financial (0–100) | F4: Ejecutiva de zona (ficticia) | G4: Ruta (demo) | J4: Prioridad | K4: Puntos | L4: Potencial | M4: Hipótesis
A5: Quilicura | B5: Zona Norte y Poniente | C5: C | D5: =VLOOKUP(C5,$J$5:$L$8,2,FALSE) | E5: =VLOOKUP(C5,$J$5:$L$8,3,FALSE) | F5: Camila Soto · Ejecutiva Zona Norte y Poniente | G5: Ruta Norte · martes y viernes | J5: A | K5: 10 | L5: 100 | M5: Alta densidad de hoteles y restaurantes de ticket alto; ruta de reparto existente.
A6: Huechuraba | B6: Zona Norte y Poniente | C6: B | D6: =VLOOKUP(C6,$J$5:$L$8,2,FALSE) | E6: =VLOOKUP(C6,$J$5:$L$8,3,FALSE) | F6: Camila Soto · Ejecutiva Zona Norte y Poniente | G6: Ruta Norte · martes y viernes | J6: B | K6: 6 | L6: 70 | M6: Alto volumen (hoteles de negocio, restaurantes, aeropuerto) con ticket medio.
A7: Vitacura | B7: Zona Oriente | C7: A | D7: =VLOOKUP(C7,$J$5:$L$8,2,FALSE) | E7: =VLOOKUP(C7,$J$5:$L$8,3,FALSE) | F7: Paula Díaz · Ejecutiva Zona Oriente | G7: Ruta Oriente · martes y jueves | J7: C | K7: 3 | L7: 40 | M7: Cobertura con menor frecuencia de ruta.
A8: Lo Barnechea | B8: Zona Oriente | C8: A | D8: =VLOOKUP(C8,$J$5:$L$8,2,FALSE) | E8: =VLOOKUP(C8,$J$5:$L$8,3,FALSE) | F8: Paula Díaz · Ejecutiva Zona Oriente | G8: Ruta Oriente · martes y jueves | J8: R | K8: 2 | L8: 30 | M8: Cobertura por confirmar (distribuidor o despacho).
A9: Pudahuel | B9: Zona Norte y Poniente | C9: B | D9: =VLOOKUP(C9,$J$5:$L$8,2,FALSE) | E9: =VLOOKUP(C9,$J$5:$L$8,3,FALSE) | F9: Camila Soto · Ejecutiva Zona Norte y Poniente | G9: Ruta Norte · martes y viernes
A10: Renca | B10: Zona Norte y Poniente | C10: C | D10: =VLOOKUP(C10,$J$5:$L$8,2,FALSE) | E10: =VLOOKUP(C10,$J$5:$L$8,3,FALSE) | F10: Camila Soto · Ejecutiva Zona Norte y Poniente | G10: Ruta Norte · martes y viernes
A11: Independencia | B11: Zona Centro | C11: C | D11: =VLOOKUP(C11,$J$5:$L$8,2,FALSE) | E11: =VLOOKUP(C11,$J$5:$L$8,3,FALSE) | F11: Andrés Rojas · Ejecutivo Zona Centro | G11: Ruta Centro · lunes, miércoles y viernes
A12: Recoleta | B12: Zona Centro | C12: C | D12: =VLOOKUP(C12,$J$5:$L$8,2,FALSE) | E12: =VLOOKUP(C12,$J$5:$L$8,3,FALSE) | F12: Andrés Rojas · Ejecutivo Zona Centro | G12: Ruta Centro · lunes, miércoles y viernes
A13: Providencia | B13: Zona Oriente | C13: A | D13: =VLOOKUP(C13,$J$5:$L$8,2,FALSE) | E13: =VLOOKUP(C13,$J$5:$L$8,3,FALSE) | F13: Paula Díaz · Ejecutiva Zona Oriente | G13: Ruta Oriente · martes y jueves
A14: Las Condes | B14: Zona Oriente | C14: A | D14: =VLOOKUP(C14,$J$5:$L$8,2,FALSE) | E14: =VLOOKUP(C14,$J$5:$L$8,3,FALSE) | F14: Paula Díaz · Ejecutiva Zona Oriente | G14: Ruta Oriente · martes y jueves
A15: Lo Prado | B15: Zona Norte y Poniente | C15: C | D15: =VLOOKUP(C15,$J$5:$L$8,2,FALSE) | E15: =VLOOKUP(C15,$J$5:$L$8,3,FALSE) | F15: Camila Soto · Ejecutiva Zona Norte y Poniente | G15: Ruta Norte · martes y viernes
A16: Quinta Normal | B16: Zona Centro | C16: C | D16: =VLOOKUP(C16,$J$5:$L$8,2,FALSE) | E16: =VLOOKUP(C16,$J$5:$L$8,3,FALSE) | F16: Andrés Rojas · Ejecutivo Zona Centro | G16: Ruta Centro · lunes, miércoles y viernes
A17: Estación Central | B17: Zona Centro | C17: C | D17: =VLOOKUP(C17,$J$5:$L$8,2,FALSE) | E17: =VLOOKUP(C17,$J$5:$L$8,3,FALSE) | F17: Andrés Rojas · Ejecutivo Zona Centro | G17: Ruta Centro · lunes, miércoles y viernes
A18: Santiago Centro | B18: Zona Centro | C18: B | D18: =VLOOKUP(C18,$J$5:$L$8,2,FALSE) | E18: =VLOOKUP(C18,$J$5:$L$8,3,FALSE) | F18: Andrés Rojas · Ejecutivo Zona Centro | G18: Ruta Centro · lunes, miércoles y viernes
A19: Ñuñoa | B19: Zona Oriente | C19: B | D19: =VLOOKUP(C19,$J$5:$L$8,2,FALSE) | E19: =VLOOKUP(C19,$J$5:$L$8,3,FALSE) | F19: Paula Díaz · Ejecutiva Zona Oriente | G19: Ruta Oriente · martes y jueves
A20: La Reina | B20: Zona Oriente | C20: B | D20: =VLOOKUP(C20,$J$5:$L$8,2,FALSE) | E20: =VLOOKUP(C20,$J$5:$L$8,3,FALSE) | F20: Paula Díaz · Ejecutiva Zona Oriente | G20: Ruta Oriente · martes y jueves
... A31: Otra región | B31: Regiones | C31: R | D31: =VLOOKUP(C31,$J$5:$L$8,2,FALSE) | E31: =VLOOKUP(C31,$J$5:$L$8,3,FALSE) | F31: Valentina Mora · Ejecutiva Regiones (remota) | G31: Despacho por transporte · plazo por confirmar

Sheet 03_FINANCIAL
A1: Financial Score v0.1 · clientes con compras
A2: Pesos originales M2 (35/30/25/10) reescalados para dar 15 % a la zona. Cuentas, montos y pedidos FICTICIOS de demostración (los mismos del prototipo).
A4: Componente | B4: Peso | C4: Normalización (0–100)
A5: Ticket promedio | B5: 0.3 | C5: MIN(100; ticket / 5.000)
A6: Frecuencia | B6: 0.25 | C6: MIN(100; (pedidos en 180 días / 6) / 4 × 100)
A7: Margen relativo | B7: 0.2 | C7: Dato 0–100 (por confirmar con finanzas)
A8: Amplitud | B8: 0.1 | C8: MIN(100; categorías / 5 × 100)
A9: Zona | B9: 0.15 | C9: Potencial de la comuna (02_ZONAS)
A10: Suma de pesos (debe ser 100 %) | B10: =SUM(B5:B9)
A12: Cliente (ficticio) | B12: Tipo | C12: Comuna | D12: Ticket promedio (CLP, ficticio) | E12: Pedidos 180 días | F12: Margen relativo | G12: Categorías | H12: Ticket n | I12: Frecuencia n | J12: Margen n | K12: Amplitud n | L12: Zona n | M12: Financial (Excel) | N12: Financial (prototipo) | O12: Diferencia | P12: Tipo de cliente (prototipo)
A13: Hotel Altos del Parque | B13: Hotel | C13: Vitacura | D13: 432366 | E13: 13 | F13: 72 | G13: 4 | H13: =MIN(100,D13/5000) | I13: =MIN(100,(E13/6)/4*100) | J13: =F13 | K13: =MIN(100,G13/5*100) | L13: =VLOOKUP(C13,'02_ZONAS'!$A$5:$E$31,5,FALSE) | M13: =ROUND(H13*$B$5+I13*$B$6+J13*$B$7+K13*$B$8+L13*$B$9,0) | N13: 77 | O13: =M13-N13 | P13: Frecuente
A14: Restaurante Fogón 21 | B14: Restaurante | C14: Las Condes | D14: 270571 | E14: 19 | F14: 64 | G14: 3 | H14: =MIN(100,D14/5000) | I14: =MIN(100,(E14/6)/4*100) | J14: =F14 | K14: =MIN(100,G14/5*100) | L14: =VLOOKUP(C14,'02_ZONAS'!$A$5:$E$31,5,FALSE) | M14: =ROUND(H14*$B$5+I14*$B$6+J14*$B$7+K14*$B$8+L14*$B$9,0) | N14: 70 | O14: =M14-N14 | P14: Frecuente
A15: Café La Esquina Verde | B15: Cafetería | C15: Ñuñoa | D15: 176500 | E15: 25 | F15: 58 | G15: 4 | H15: =MIN(100,D15/5000) | I15: =MIN(100,(E15/6)/4*100) | J15: =F15 | K15: =MIN(100,G15/5*100) | L15: =VLOOKUP(C15,'02_ZONAS'!$A$5:$E$31,5,FALSE) | M15: =ROUND(H15*$B$5+I15*$B$6+J15*$B$7+K15*$B$8+L15*$B$9,0) | N15: 66 | O15: =M15-N15 | P15: Frecuente
A16: Hotel Plaza Moneda | B16: Hotel | C16: Santiago Centro | D16: 304318 | E16: 8 | F16: 55 | G16: 3 | H16: =MIN(100,D16/5000) | I16: =MIN(100,(E16/6)/4*100) | J16: =F16 | K16: =MIN(100,G16/5*100) | L16: =VLOOKUP(C16,'02_ZONAS'!$A$5:$E$31,5,FALSE) | M16: =ROUND(H16*$B$5+I16*$B$6+J16*$B$7+K16*$B$8+L16*$B$9,0) | N16: 54 | O16: =M16-N16 | P16: Frecuente
A17: Café Bistró Providencia | B17: Restaurante | C17: Providencia | D17: 146235 | E17: 12 | F17: 61 | G17: 2 | H17: =MIN(100,D17/5000) | I17: =MIN(100,(E17/6)/4*100) | J17: =F17 | K17: =MIN(100,G17/5*100) | L17: =VLOOKUP(C17,'02_ZONAS'!$A$5:$E$31,5,FALSE) | M17: =ROUND(H17*$B$5+I17*$B$6+J17*$B$7+K17*$B$8+L17*$B$9,0) | N17: 52 | O17: =M17-N17 | P17: Frecuente
A18: Bistró Los Aromos | B18: Restaurante | C18: La Reina | D18: 128300 | E18: 8 | F18: 52 | G18: 2 | H18: =MIN(100,D18/5000) | I18: =MIN(100,(E18/6)/4*100) | J18: =F18 | K18: =MIN(100,G18/5*100) | L18: =VLOOKUP(C18,'02_ZONAS'!$A$5:$E$31,5,FALSE) | M18: =ROUND(H18*$B$5+I18*$B$6+J18*$B$7+K18*$B$8+L18*$B$9,0) | N18: 41 | O18: =M18-N18 | P18: Frecuente
A19: Hotel Terminal Aéreo | B19: Hotel | C19: Pudahuel | D19: 378879 | E19: 16 | F19: 49 | G19: 3 | H19: =MIN(100,D19/5000) | I19: =MIN(100,(E19/6)/4*100) | J19: =F19 | K19: =MIN(100,G19/5*100) | L19: =VLOOKUP(C19,'02_ZONAS'!$A$5:$E$31,5,FALSE) | M19: =ROUND(H19*$B$5+I19*$B$6+J19*$B$7+K19*$B$8+L19*$B$9,0) | N19: 66 | O19: =M19-N19 | P19: Frecuente
A20: Cafetería Los Maitenes | B20: Cafetería | C20: Huechuraba | D20: 137364 | E20: 6 | F20: 57 | G20: 1 | H20: =MIN(100,D20/5000) | I20: =MIN(100,(E20/6)/4*100) | J20: =F20 | K20: =MIN(100,G20/5*100) | L20: =VLOOKUP(C20,'02_ZONAS'!$A$5:$E$31,5,FALSE) | M20: =ROUND(H20*$B$5+I20*$B$6+J20*$B$7+K20*$B$8+L20*$B$9,0) | N20: 38 | O20: =M20-N20 | P20: Frecuente
A21: Cafetería Plaza Poniente | B21: Cafetería | C21: Maipú | D21: 92615 | E21: 8 | F21: 44 | G21: 1 | H21: =MIN(100,D21/5000) | I21: =MIN(100,(E21/6)/4*100) | J21: =F21 | K21: =MIN(100,G21/5*100) | L21: =VLOOKUP(C21,'02_ZONAS'!$A$5:$E$31,5,FALSE) | M21: =ROUND(H21*$B$5+I21*$B$6+J21*$B$7+K21*$B$8+L21*$B$9,0) | N21: 31 | O21: =M21-N21 | P21: Frecuente
A22: Picada El Sur | B22: Restaurante | C22: La Florida | D22: 93500 | E22: 2 | F22: 40 | G22: 1 | H22: =MIN(100,D22/5000) | I22: =MIN(100,(E22/6)/4*100) | J22: =F22 | K22: =MIN(100,G22/5*100) | L22: =VLOOKUP(C22,'02_ZONAS'!$A$5:$E$31,5,FALSE) | M22: =ROUND(H22*$B$5+I22*$B$6+J22*$B$7+K22*$B$8+L22*$B$9,0) | N22: 24 | O22: =M22-N22 | P22: Inactivo
A23: Eventos Cordillera | B23: Eventos o catering | C23: Lo Barnechea | D23: 518667 | E23: 4 | F23: 68 | G23: 4 | H23: =MIN(100,D23/5000) | I23: =MIN(100,(E23/6)/4*100) | J23: =F23 | K23: =MIN(100,G23/5*100) | L23: =VLOOKUP(C23,'02_ZONAS'!$A$5:$E$31,5,FALSE) | M23: =ROUND(H23*$B$5+I23*$B$6+J23*$B$7+K23*$B$8+L23*$B$9,0) | N23: 71 | O23: =M23-N23 | P23: Ocasional
A24: Hostal Patio Recoleta | B24: Hotel | C24: Recoleta | D24: 70600 | E24: 5 | F24: 46 | G24: 1 | H24: =MIN(100,D24/5000) | I24: =MIN(100,(E24/6)/4*100) | J24: =F24 | K24: =MIN(100,G24/5*100) | L24: =VLOOKUP(C24,'02_ZONAS'!$A$5:$E$31,5,FALSE) | M24: =ROUND(H24*$B$5+I24*$B$6+J24*$B$7+K24*$B$8+L24*$B$9,0) | N24: 27 | O24: =M24-N24 | P24: Frecuente
... A32: Catering El Portal | B32: Eventos o catering | C32: San Miguel | D32: 97833 | E32: 5 | F32: 45 | G32: 1 | H32: =MIN(100,D32/5000) | I32: =MIN(100,(E32/6)/4*100) | J32: =F32 | K32: =MIN(100,G32/5*100) | L32: =VLOOKUP(C32,'02_ZONAS'!$A$5:$E$31,5,FALSE) | M32: =ROUND(H32*$B$5+I32*$B$6+J32*$B$7+K32*$B$8+L32*$B$9,0) | N32: 28 | O32: =M32-N32 | P32: Frecuente
A34: Tipo de cliente: Nuevo = primera compra en los últimos 90 días; Ocasional = 1 o 2 compras en 90 días; Frecuente = más de 2; Inactivo = sin compras en 90 días.

Sheet 04_KPIS
A1: KPIs comerciales, operacionales, de inbound y de experiencia
A2: Matriz propuesta. Ninguna cifra es resultado medido. Las metas académicas del caso se citan con su fuente [3]; el resto se fija tras levantar línea base.
A4: ID | B4: KPI | C4: Tipo | D4: Fórmula | E4: Unidad | F4: Ventana / período | G4: Fuente de datos | H4: Frecuencia | I4: Responsable | J4: Línea base | K4: Umbral o meta propuesta | L4: Decisión que apoya
A5: K01 | B5: Tasa de acceso Empresas | C5: Captación | D5: Clics únicos en Empresas / sesiones del inicio × 100 | E5: % | F5: Semanal | G5: Analítica web (eventos) | H5: Semanal | I5: Marketing | J5: [A LEVANTAR] | K5: Definir tras 4 semanas | L5: Ubicación y rótulo del acceso
A6: K02 | B6: Tasa de identificación | C6: Inbound | D6: Contactos con correo y permiso / sesiones que inician tus datos × 100 | E6: % | F6: Semanal | G6: Eventos del formulario + consentimiento | H6: Semanal | I6: Marketing | J6: [A LEVANTAR] | K6: Definir tras 4 semanas | L6: Campos y explicación de uso
A7: K03 | B7: Finalización del diagnóstico | C7: Activación | D7: Sesiones que terminan los 3 pasos y ven su propuesta / sesiones que iniciaron × 100 | E7: % | F7: Semanal | G7: Eventos del portal | H7: Semanal | I7: Marketing / UX | J7: [A LEVANTAR] | K7: Definir tras 4 semanas | L7: Orden y redacción de los pasos
A8: K04 | B8: Pedido de contacto humano | C8: Activación | D8: Contactos que solicitan revisión o propuesta por correo / propuestas vistas × 100 | E8: % | F8: Semanal | G8: CRM (R02) | H8: Semanal | I8: Ventas | J8: [A LEVANTAR] | K8: Definir tras 4 semanas | L8: Canal por defecto y disponibilidad
A9: K05 | B9: Primera respuesta humana en chat | C9: Servicio | D9: Mediana (primera respuesta de la ejecutiva − ingreso al chat), por zona | E9: min | F9: Diaria | G9: CRM (marcas de tiempo) | H9: Diaria | I9: Jefatura comercial | J9: [A LEVANTAR] | K9: ≤ 5 min (hipótesis del equipo) | L9: Dotación por zona y horario
A10: K06 | B10: Llamadas en plazo | C10: Servicio | D10: Llamadas realizadas dentro de la hora o del plazo informado / llamadas pedidas × 100 | E10: % | F10: Semanal | G10: CRM (cola de llamadas) | H10: Semanal | I10: Jefatura comercial | J10: [A LEVANTAR] | K10: Definir con capacidad real | L10: Reasignar entre zonas
A11: K07 | B11: Tasa MQL | C11: Calificación | D11: MQL / contactos identificados × 100, por zona | E11: % | F11: Mensual | G11: CRM + puntaje | H11: Mensual | I11: Marketing | J11: [A LEVANTAR] | K11: Definir tras calibrar | L11: Calibrar pesos y zonas
A12: K08 | B12: Tasa SQL | C12: Calificación | D12: SQL aceptados por una persona / MQL × 100, por zona | E12: % | F12: Mensual | G12: CRM | H12: Mensual | I12: Ventas | J12: [A LEVANTAR] | K12: Definir tras calibrar | L12: Calidad de leads por zona
A13: K09 | B13: Aceptación de propuesta | C13: Cierre | D13: Propuestas aceptadas / propuestas enviadas × 100; % ampliada | E13: % | F13: Mensual | G13: CRM (R08) | H13: Mensual | I13: Ventas | J13: [A LEVANTAR] | K13: Definir tras piloto | L13: Contenido de base y ampliada
A14: K10 | B14: Lead a cliente | C14: Cierre | D14: Clientes nuevos / leads de la cohorte × 100 | E14: % | F14: Trimestral (cohorte) | G14: CRM + ventas | H14: Mensual | I14: Gerencia comercial | J14: 12 % (supuesto académico [3]) | K14: 18 % (meta académica [3]) | L14: Escalar o ajustar el MVP
A15: K11 | B15: Reposición digital | C15: Recompra | D15: Reposiciones por canal digital / reposiciones totales × 100 | E15: % | F15: Mensual | G15: Pedidos + CRM | H15: Mensual | I15: Ejecutivos de cuenta | J15: 18 % (supuesto académico [3]) | K15: 40 % a 12 meses (meta académica [3]) | L15: Recompra en un toque y W7
... A36: K32 | B36: Reposiciones manuales | C36: Recompra | D36: Reposiciones pedidas por ejecutiva, correo o mensaje / reposiciones totales × 100 | E36: % | F36: Mensual | G36: CRM + pedidos | H36: Mensual | I36: Ejecutivos de cuenta | J36: 82 % (supuesto académico [3]) | K36: Bajarlo respecto del 82 % con la reposición en un toque | L36: W7, aviso por frecuencia y portal Mi cuenta

Sheet 05_WORKFLOWS
A1: Workflows de inbound automatizado
A2: Recorrido vigente19oct: C02 → C10 Productos → C11 Máquinas/condiciones → C03 Contacto → C04 Diagnóstico → C05 Propuesta → C06 Folio. W1 solo con correo y permiso; la cesta no crea consentimiento ni puntaje. Edición posterior exige nueva revisión; W4/W5 por correo y WhatsApp solo en postventa entrante.
A4: ID | B4: Nombre | C4: Segmento | D4: Etapa del funnel | E4: Gatillador (evento) | F4: Condición | G4: Espera | H4: Canal | I4: Acción y contenido | J4: Supresión / salida | K4: KPI | L4: Dónde se ve en el prototipo
A5: W1 | B5: Contacto nuevo | C5: Todos | D5: Identificación | E5: Tras explorar productos (C10) y máquinas (C11), deja datos con permiso (C03, antes del diagnóstico) | F5: Correo válido + permiso | G5: Inmediato | H5: Correo + CRM | I5: Correo con su N.º de seguimiento (la propuesta le llega al terminar, W2); ficha en el CRM; aviso a la ejecutiva | J5: — | K5: K02 | L5: C10/C11 preceden a C03; correo local y R01. Productos/cantidades y preferencia conservados hasta R02/R08.
A6: W2 | B6: Calificación y zona | C6: Por tipo de negocio y comuna | D6: Evaluación | E6: Marca su negocio y su comuna (C04, pasos 1 y 2) | F6: Comuna informada | G6: Inmediato | H6: Interno | I6: Suma puntaje (A +10, B +6, C +3, R +2); asigna ejecutiva de la zona; Logística revisa ruta; al terminar, el agente arma la propuesta y se la envía por correo | J6: — | K6: K07 | L6: R07 Agentes; R04
A7: W3 | B7: Propuesta aceptada o contacto humano | C7: Todos | D7: Activación | E7: Solicita revisión de su propuesta por correo (C05 → C06; si faltan datos, C03) | F7: Disponibilidad de la ejecutiva | G7: Inmediato | H7: Chat consultivo y correo comercial | I7: Solicitud registrada con folio, resumen y correo. La ejecutiva revisa condiciones y responde por correo; no confirma contrato ni instalación | J7: Sale cuando la ejecutiva responde (W6) | K7: K04, K05, K06, K09 | L7: C06; R02
A8: W4 | B8: Abandono con datos | C8: Con correo y permiso (dejó sus datos al principio) | D8: Evaluación | E8: Dejó sus datos y no terminó el diagnóstico, o vio su propuesta y no la aceptó ni pidió contacto | F8: Sin actividad ni atención humana activa; permiso por finalidad; recuperación solo por correo | G8: 24 h | H8: Correo + remarketing con permiso | I8: «Tu avance te espera» o «Tu propuesta te espera» con el video de su negocio (máx. 1); entra a la audiencia de remarketing (Google y Meta) con permiso | J8: Retoma, acepta o pasa a nutrición (W10) | K8: K03, K09 | L8: Simulado: aviso a los 2 min sin terminar (en la realidad, 24 h)
A9: W5 | B9: Propuesta sin respuesta | C9: SQL candidato | D9: Cierre | E9: Propuesta enviada por la ejecutiva (R02 o R08) | F9: Sin aceptación | G9: 72 h | H9: Correo | I9: Seguimiento de la ejecutiva con el resumen de su propuesta y los extras que marcó | J9: Acepta o cierra la secuencia | K9: K09 | L9: Diseñado (no simulado)
A10: W6 | B10: Toma humana | C10: Todos | D10: Activación / cierre | E10: La ejecutiva responde por correo | F10: — | G10: Inmediato | H10: — | I10: Pausa W4, W5 y respuestas autónomas de IA; conserva contexto y responsable para no duplicar mensajes | J10: — | K10: — | L10: R02 (pausa la ejecutiva simulada)
A11: W7 | B11: Recompra | C11: Cliente activo | D11: Recompra | E11: Días sin comprar ≥ su frecuencia habitual | F11: Sin incidencia crítica | G11: Según frecuencia del cliente | H11: Portal y correo; WhatsApp solo entrante | I11: Borrador del último pedido con cantidades y dirección; cliente revisa y confirma antes de crearlo; ejecutivo resuelve excepciones y Logística confirma ruta | J11: Repite pedido o contacto | K11: K11, K12 | L11: R01 Recompras; C09
A12: W8 | B12: Referidos | C12: Financial ≥ 70 | D12: Recompra | E12: Cliente frecuente y satisfecho | F12: Sin incidencia crítica | G12: — | H12: Portal | I12: Invitación con código de referido; beneficio lo aprueba jefatura | J12: Referido atribuido | K12: K15 | L12: C09; R07 aprobaciones
A13: W9 | B13: Incidencia crítica | C13: Cliente activo | D13: Postventa | E13: Ticket crítico abierto | F13: — | G13: Inmediato | H13: Portal/chat; WhatsApp postventa entrante | I13: Crea ticket con número, responsable y estado; pausa ampliación, campañas y referidos; traspasa a postventa con contexto | J13: Cliente confirma solución; si no, reabrir; baja de marketing se respeta | K13: K21 | L13: Recorrido demostrable; integración real propuesta en hoja 23
A14: W10 | B14: Nutrición por zona | C14: Puntaje < 40; zona A/B vs C/R | D14: Exploración | E14: Contacto identificado que no avanza | F14: Con permiso | G14: 3, 7 y 14 días | H14: Correo | I14: A/B: guía gráfica + video del caso + invitación al diagnóstico. C/R: guía + cobertura y despacho de su zona | J14: Pide contacto o se da de baja | K14: K03, K07 | L14: Diseñado (no simulado)

Sheet 06_CONTENIDOS
A1: Piezas audiovisuales y gráficas por etapa del funnel
A2: Estado al 10-10-2026. Solo se publican piezas con información verificable y autorizada por Marley Coffee.
A4: Pieza | B4: Formato | C4: Etapa | D4: Segmento | E4: Objetivo | F4: CTA | G4: Workflow | H4: Estado
A5: Video caso hotel (8 s) | B5: Audiovisual | C5: Exploración / espera | D5: Hotel, eventos | E5: Imaginar Marley Coffee en su operación | F5: Encontrar mi solución | G5: W3, W4 | H5: Producido para el MVP (Higgsfield)
A6: Video caso restaurante (8 s) | B6: Audiovisual | C6: Exploración / espera | D6: Restaurante, cafetería | E6: Imaginar el espresso de sobremesa con la marca | F6: Encontrar mi solución | G6: W3, W4 | H6: Producido para el MVP (Higgsfield)
A7: Experiencia de casos con scroll (C08) | B7: Audiovisual interactivo | C7: Evaluación | D7: Todos | E7: Comparar formatos por tipo de negocio | F7: Encontrar mi solución | G7: — | H7: Producido en el prototipo
A8: Fotos oficiales de producto | B8: Gráfico | C8: Evaluación | D8: Todos | E8: Mostrar el catálogo real sin precios | F8: Ver propuesta | G8: — | H8: Disponible (catálogo oficial)
A9: Correo con la propuesta y el N.º de seguimiento | B9: Texto + marca | C9: Identificación | D9: Todos | E9: Retomar sin repetir datos | F9: Volver a mi portal | G9: W1 | H9: Simulado en el prototipo
A10: Guía gráfica «Qué datos sirven para recomendarte» | B10: Gráfico | C10: Exploración | D10: Todos | E10: Bajar la duda antes del diagnóstico | F10: Empezar diagnóstico | G10: W10 | H10: Por producir
A11: Comparador visual grano / molido / cápsulas | B11: Gráfico | C11: Evaluación | D11: Por forma de servicio | E11: Elegir formato | F11: Ver mi recomendación | G11: W4 | H11: Por producir con datos aprobados
A12: Correo «Tu propuesta te espera» con video | B12: Audiovisual + texto | C12: Evaluación | D12: Puntaje ≥ 40 | E12: Recuperar a quien vio su propuesta y no la aceptó | F12: Aceptar mi propuesta | G12: W4 | H12: Por producir
A13: Clip para redes por zona (Oriente) | B13: Audiovisual | C13: Descubrimiento | D13: Zona A | E13: Atraer hoteles y restaurantes de alto ticket | F13: Empresas | G13: — | H13: Por producir
A14: Caso real HORECA | B14: Audiovisual / gráfico | C14: Evaluación | D14: Por tipo de negocio | E14: Prueba social verificable | F14: Encontrar mi solución | G14: — | H14: Pendiente de autorización de un cliente real
A16: ID | B16: Etapa del ciclo | C16: Táctica | D16: Público | E16: Acción | F16: Pieza | G16: Valor / CTA | H16: Evento y automatización | I16: Agente | J16: Indicador | K16: Medición | L16: Estado
A17: T01 | B17: Atraer | C17: SEO por intención profesional | D17: Administración de hoteles, restaurantes, cafeterías y eventos | E17: Crear /empresas y páginas útiles por negocio; enlazar desde Empresas, catálogo pertinente y guías. Explicar comodato y abastecimiento mensual con respuestas propias de cada operación. | F17: Páginas por negocio con una solución, comparador y preguntas frecuentes visibles. | G17: LM1 | H17: visita_empresas · W1 | I17: Marketing | J17: K01, K02 | K17: Impresiones y clics por intención; visitas a Empresas; contacto identificado. W1 solo al guardar datos con permiso. | L17: Arquitectura propuesta para producción: /empresas y destinos por intención. Las rutas hash del HTML local son navegación de demostración.
A18: T02 | B18: Atraer | C18: SEO técnico y estructura semántica | D18: Responsable que busca una máquina para su operación | E18: Validar rastreo e indexación; corregir la referencia genérica a MiTienda.com.br observada en robots.txt, publicar sitemap de URLs públicas correctas, canonical y metadatos únicos, un H1 descriptivo y enlaces rastreables. Diseñar páginas B2B indexables desde el servidor; no depender de rutas hash del prototipo. Excluir portal/CRM del índice y protegerlos con autenticación. | F18: Mapa de URLs públicas, sitemap y control en Search Console; datos estructurados fieles al contenido visible. | G18: LM1 | H18: visita_organica_empresas · W1 | I18: Marketing + TI | J18: K01 | K18: URLs indexables e indexadas, errores de cobertura y clics. La lectura del sitio del 15-10 confirma la referencia genérica en robots; cambios y rendimiento por validar con accesos reales. | L18: Táctica propuesta; publicación, accesos y resultados del piloto pendientes de validación.
A19: T03 | B19: Atraer | C19: SEM de búsqueda por intención | D19: Quien compara proveedores o modalidades para su negocio | E19: Separar intención de abastecimiento HORECA, equipos en comodato y café por negocio. Anuncio y destino explican el servicio real; excluir ofertas de venta/arriendo de equipos no disponibles. Medir términos y calidad de contactos, sin prometer posiciones ni rentabilidad. | F19: Tres grupos de búsqueda, anuncio por intención y destino por negocio/modalidad; etiquetas UTM. | G19: LM1 | H19: visita_campana_empresas · W1 | I19: Marketing + revisión comercial | J19: K01, K02, K08, K10 | K19: Clic, costo por contacto y SQL aceptado; comparar calidad por intención y zona. Sin presupuesto ni rentabilidad supuestos. | L19: Táctica propuesta; publicación, accesos y resultados del piloto pendientes de validación.
A20: T04 | B20: Atraer | C20: Orgánico útil en LinkedIn | D20: Administradores de hotel y responsables de alimentos y bebidas | E20: Publicar carrusel de planificación del café de desayuno: turnos, volumen aproximado, capacitación y reposición. Enlazar con UTM a guía y diagnóstico de hotel; ejemplos ilustrativos rotulados. | F20: Carrusel «Qué considerar para el café de tu hotel» y guía de datos necesarios. | G20: LM1, LM3 | H20: visita_linkedin_hotel · W1, W2 | I20: Marketing | J20: K01, K03, K07 | K20: Clic al activo, identificación, diagnóstico y MQL; no tratar alcance como venta. | L20: Táctica propuesta; publicación, accesos y resultados del piloto pendientes de validación.
A21: T05 | B21: Atraer | C21: Orgánico útil en Instagram | D21: Dueños de cafeterías/restaurantes y productores de eventos | E21: Crear clip de sobremesa o barra y carrusel grano/molido/cápsulas con criterios de elección; enlazar pieza por negocio mediante UTM. Mostrar productos oficiales e identificar escenas generadas como ilustrativas. | F21: Clip por negocio + comparador visual + destino relevante. | G21: LM1, LM3 | H21: visita_instagram_negocio · W1, W2 | I21: Marketing | J21: K01, K03 | K21: Guardados y clics al destino; finalización del diagnóstico por pieza y negocio. | L21: Táctica propuesta; publicación, accesos y resultados del piloto pendientes de validación.
A22: T06 | B22: Atraer | C22: Activaciones, alianzas y referidos | D22: Asistentes a activaciones y negocios invitados por clientes | E22: Vincular QR de una activación y código de referido con la página pertinente; ofrecer orientación útil. Publicar casos reales solo con autorización y evidencia, sin convertir escenas de ejemplo en testimonios. | F22: QR identificado, código referido y caso autorizado cuando exista. | G22: LM1, LM7 | H22: visita_activacion_o_referido · W8, W1 | I22: Marketing + Postventa | J22: K01, K15 | K22: Origen de activación o referido conservado hasta contacto/cliente. W8 nace del cliente que invita. | L22: Táctica propuesta; publicación, accesos y resultados del piloto pendientes de validación.
A23: T07 | B23: Interactuar | C23: Correo y diagnóstico conectados | D23: Contacto identificado por negocio, zona e intención | E23: Guardar datos con permiso, enviar número de seguimiento, conservar avance y construir propuesta al terminar; mostrar en CRM correo, canal, zona y variación del puntaje. | F23: Correo documental + diagnóstico de tres pasos + propuesta personalizada. | G23: LM2, LM3 | H23: contacto_identificado / diagnostico_terminado · W1, W2 | I23: Calificación + Ventas + Logística | J23: K02, K03, K07 | K23: Identificación, finalización y MQL; correo aceptado/clic si el proveedor lo confirma. | L23: Táctica propuesta; publicación, accesos y resultados del piloto pendientes de validación.
A24: T08 | B24: Interactuar | C24: Recuperación y nutrición por contexto | D24: Persona que dejó avance y no volvió | E24: W4 revisa inactividad a las 24 h y hace como máximo un aviso con la pieza de su negocio; W10 nutre a puntaje <40 con permiso a los 3, 7 y 14 días. Remarketing solo con permiso y exclusiones actualizadas. | F24: Correo «Tu avance/propuesta te espera», guía por zona y audiencia autorizada. | G24: LM2, LM3 | H24: inactividad_24h / nutricion_programada · W4, W10, W6 | I24: Marketing + Calificación | J24: K03, K07, K09 | K24: Avances retomados, propuesta aceptada y bajas; pausar recuperación al retomar o ser atendido. | L24: Táctica propuesta; publicación, accesos y resultados del piloto pendientes de validación.
A25: T09 | B25: Interactuar | C25: Conversación asistida y cierre humano | D25: Quien acepta, pregunta o compara extras | E25: IA explica recomendación y prepara resumen; la ejecutiva recibe conversación, propuesta y canal. Registrar respuesta y pausar IA/secuencias; revisar seguimiento a las 72 h solo si la propuesta sigue sin respuesta. | F25: Chat consultivo y correo con una ficha y responsable; propuesta base/ampliada. | G25: LM3, LM4 | H25: contacto_solicitado / propuesta_aceptada / respuesta_humana · W3, W5, W6 | I25: Ventas + ejecutiva | J25: K04, K05, K06, K08, K09, K10 | K25: Respuesta humana, SQL aceptado, aceptación y conversión; plazo de 5 min es hipótesis, no garantía. | L25: Táctica propuesta; publicación, accesos y resultados del piloto pendientes de validación.
A26: T10 | B26: Deleitar | C26: Reposición útil antes del quiebre | D26: Cliente activo con frecuencia conocida | E26: Preparar el último pedido según frecuencia; avisar por portal o correo. El cliente revisa y confirma; Logística valida ruta. WhatsApp solo si el cliente inicia postventa. | F26: Aviso de reposición + borrador en portal + seguimiento del pedido. | G26: LM5 | H26: frecuencia_cumplida / reposicion_confirmada · W7, W9 | I26: Postventa + Logística | J26: K11, K12, K16, K27 | K26: Reposición digital, frecuencia y entrega completa a tiempo; no enviar promoción si hay incidencia crítica. | L26: Táctica propuesta; publicación, accesos y resultados del piloto pendientes de validación.
A27: T11 | B27: Deleitar | C27: Servicio omnicanal con pausa comercial | D27: Cliente con problema en máquina, pedido o entrega | E27: Abrir ticket con número, adjuntos opcionales, criticidad y responsable; IA consulta estado y deriva con contexto; cliente confirma solución o reabre. Pausar ampliación y campañas. | F27: Portal/chat/WhatsApp entrante → ticket único → estado y confirmación. | G27: LM5 | H27: ticket_critico_abierto / incidencia_resuelta · W9, W6 | I27: Postventa + Logística + ejecutiva | J27: K21, K27 | K27: Primera respuesta y retención; estados verificables, sin prometer plazos no confirmados. | L27: Táctica propuesta; publicación, accesos y resultados del piloto pendientes de validación.
A28: T12 | B28: Deleitar | C28: Expansión y prueba social que alimentan la atracción | D28: Cliente satisfecho, sin incidencia crítica | E28: Recomendar tazas, material de marca o capacitación según operación; cliente elige. Invitar a referir si cumple Financial ≥70 y se aprueba beneficio; solicitar permiso antes de publicar su caso. | F28: Ampliación por necesidad, código de referido y caso documentado con permiso. | G28: LM4, LM6, LM7 | H28: interes_servicio / referido_atribuido · W8, W3 | I28: Postventa + Marketing + jefatura | J28: K13, K15, K27, K30, K31 | K28: Ticket, amplitud, margen y referidos convertidos; contrastar calidad de origen para mejorar atracción. | L28: Táctica propuesta; publicación, accesos y resultados del piloto pendientes de validación.
A30: Canal / táctica | B30: Segmento | C30: Intención o idea | D30: Destino o activo | E30: Ejemplo de pieza / estructura | F30: Valor y siguiente acción | G30: Evento y automatización | H30: Indicador | I30: Control
A31: SEO · T01/T02 | B31: Hoteles | C31: Máquina de café para hotel; café para desayuno y habitaciones | D31: /empresas/hoteles (URL propuesta) | E31: Título/H1 sobre café para hoteles; comparar Bar para desayuno y Pods para habitaciones; preguntas visibles sobre operación, sin tarifas inventadas. | F31: LM1: ver solución de su hotel → Ver mi solución | G31: visita_organica_empresas → contacto_identificado / W1; diagnóstico / W2 | H31: K01 visitas; K02 identificación; K07 MQL | I31: Publicar URL indexable, canonical y enlaces; validar sitemap/Search Console. No publicar el portal ni depender del hash local.
A32: SEO · T01/T02 | B32: Restaurantes | C32: Máquina de café para restaurante; café de sobremesa | D32: /empresas/restaurantes (URL propuesta) | E32: Contenido sobre servicio de sobremesa; comparar Pods sin barista y Bar con equipo; explicar comodato y abastecimiento mensual. | F32: LM1: comparación útil → Ver mi solución | G32: visita_organica_empresas → W1 al dejar datos; W2 al completar negocio/comuna | H32: K01, K02, K07 | I32: Vincular catálogo y guía; preguntas propias del negocio. No prometer posiciones ni resultados enriquecidos.
A33: SEO · T01/T02 | B33: Cafeterías | C33: Café en grano para cafetería; arriendo o compra de máquina profesional | D33: /empresas/cafeterias (URL propuesta) | E33: Página de barra, consumo y capacitación; explicar costo mensual frente a pago único, café y extras por separado. | F33: LM1/LM3: recomendación según operación → Ver propuesta | G33: visita_organica_empresas → W1/W2 → propuesta vista | H33: K01, K02, K07, K08 | I33: Producto y disponibilidad verificados para producción; rangos académicos no se publican como oferta real.
A34: SEO · T01/T02 | B34: Eventos y catering | C34: Coffee break para empresas; servicio de café para eventos | D34: /empresas/eventos (URL propuesta) | E34: Contenido sobre volumen, duración y servicio con barista o autoservicio; condiciones y cobertura por confirmar. | F34: LM1: imaginar el servicio → Ver mi solución | G34: visita_organica_empresas → W1/W2 | H34: K01, K02, K07 | I34: Casos y fotografías reales solo con evidencia y permiso; rotular recreaciones del prototipo.
A35: SEM · T03 | B35: Demanda de comodato | C35: Campaña Search Empresas / grupo Comodato | D35: /empresas/maquinas (URL propuesta; condiciones de comodato) | E35: Ejemplo propuesto: Café para tu negocio · equipo en comodato con compra mensual de insumos. Destino conecta catálogo y equipos antes de contacto. Términos por validar. | F35: LM1: comparador → Ver mi solución | G35: visita_campana_empresas con UTM → W1/W2 | H35: K01, K02, K07; costo por MQL y venta por levantar | I35: Presupuesto y puja sin definir. Revisar negativas de empleo, uso doméstico o búsquedas no atendibles antes de excluir; no anunciar beneficios no confirmados.
A36: SEM · T03 | B36: Demanda de abastecimiento | C36: Campaña Search Empresas / grupo Insumos | D36: /empresas/productos (URL propuesta; catálogo B2B) | E36: Ejemplo propuesto: Café e insumos para tu negocio · arma tu abastecimiento. Precio profesional y formatos sujetos a validación; no usar precio público B2C como tarifa mayorista. | F36: LM1/LM3: comparar modalidades → Ver propuesta | G36: visita_campana_empresas → W1/W2 → W3 al aceptar o pedir contacto | H36: K01, K02, K07, K09 | I36: Stock, precio y condiciones reales antes de activar. No usar los montos de demostración como oferta publicitaria.
A37: SEM · T03 | B37: Café y servicios HORECA | C37: Campaña Search Empresas / grupo Café HORECA | D37: Página del negocio correspondiente (URLs propuestas) | E37: Anuncio según hotel, restaurante, cafetería o evento; consulta y destino coherentes. Términos reales y negativas se revisan en el piloto. | F37: LM1: solución de su negocio → Diagnóstico breve | G37: visita_campana_empresas → W1/W2; venta confirmada al CRM y medición autorizada | H37: K01, K02, K07, K09; atribución a venta por validar | I37: Data Manager se propone para conversiones posteriores; requiere acceso, acción de conversión y consentimiento. No se crea campaña ni gasto en esta entrega.
A38: Orgánico · LinkedIn · T04 | B38: Administración de hoteles/restaurantes | C38: Carrusel: «Qué revisar antes de elegir el café de tu local» | D38: Publicación con UTM a /empresas y página de negocio | E38: 5 láminas: operación, volumen, forma de servicio, modalidad y siguiente paso. Foto de producto oficial y escena demostrativa identificada. | F38: LM1: lista útil para comparar → Ver mi solución | G38: visita_social_empresas → W1 solo al dejar contacto con permiso | H38: K01 tráfico referido; K02; K07; guardados/interacciones como apoyo | I38: Contenido educativo, sin testimonios ni mejoras cuantificadas inventadas. Llevar cada pieza al destino correspondiente.
A39: Orgánico · Instagram · T05 | B39: Operadores de cafeterías y eventos | C39: Clip breve: café servido y máquina según el contexto | D39: Video por negocio con enlace/UTM a destino propuesto | E39: Ejemplo: 12–20 s de preparación, beneficio operativo claro y cierre de una acción. Un producto protagonista y texto legible sin sonido. | F39: LM1: visualizar experiencia → Comparar solución | G39: visita_social_empresas → W1/W2; consulta por chat conserva referencia | H39: K01, K02, K07; reproducción y guardados como apoyo | I39: Mostrar equipo coherente; piezas de recreación se identifican. No presentar escenas generadas como clientes o casos de éxito reales.

Sheet 07_TEST_PLAN
A1: Plan de test de usabilidad (ronda 1 realizada el 15-10-2026)
A2: Test moderado, pensando en voz alta, dentro del prototipo («Iniciar test»). Ronda 1: 5 participantes con código (sin nombres): P1 computador, P2 y P3 celular en el sitio (T1, con las palabras de su negocio); P4 computador (T7) y P5 celular (T9) en el CRM. Nielsen (2000) [23] recomienda 5 por ronda. Una tarea por persona: las demás quedan como recorrido de diseño. Registro automático de tiempo, toques, SEQ y SUS; mapa de calor. Ronda 2 con 2 o 3 personas después de los cambios v6 (hoja 22).
A4: ID | B4: Rol | C4: Tarea (se lee al participante) | D4: Pantallas | E4: Criterio de éxito | F4: Métricas | G4: Umbral | H4: Ronda 1 (15-10)
A5: T1 | B5: Cliente | C5: Tienes un hotel (o restaurante, cafetería, eventos) y quieres cambiar el café. Desde esta página, busca cómo pedir una propuesta para tu negocio. | D5: C01 → C02 (LM1) | E5: Llega a la propuesta sin ayuda | F5: Éxito, tiempo por etapa, toques, SEQ | G5: ≥ 80 % sin ayuda | H5: Medida: P1, P2 y P3
A6: T2 | B6: Cliente | C6: Deja tus datos, marca tu negocio y mira tu propuesta. No sabes cuántas tazas sirves al día. | D6: C03 → C04 → C05 (LM2, LM3) | E6: Deja sus datos, termina los 3 pasos y ve su propuesta | F6: Éxito, tiempo en los datos, toques, SEQ | G6: ≥ 80 %; datos ≤ 30 s; pasos ≤ 25 s y ≤ 8 toques | H6: Recorrido de diseño (dentro de T1)
A7: T3 | B7: Cliente | C7: Acepta tu propuesta o pide hablar con una persona, y cuéntale al moderador qué pasará después. | D7: C05 → C06 (LM4) | E7: Acepta o pide hablar sin que le vuelvan a pedir sus datos, y describe el siguiente paso | F7: Éxito, comprensión | G7: ≥ 80 % | H7: Recorrido de diseño (dentro de T1)
A8: T4 | B8: Cliente | C8: En tu portal, pregunta si tienen tazas con la marca. Después, cambia la forma de contacto por otra. | D8: C06 (LM4) | E8: Envía el mensaje y cambia de canal sin perder la conversación | F8: Éxito, errores, SEQ | G8: ≥ 80 % | H8: Recorrido de diseño (no medida)
A9: T5 | B9: Cliente | C9: Ajusta tu propuesta para que incluya tazas Marley Coffee y acéptala. | D9: C05 → C07 (LM4) | E9: Acepta la ampliada | F9: Éxito, tiempo en la propuesta | G9: ≥ 80 %; ≤ 30 s | H9: Recorrido de diseño (dentro de T1)
A10: T6 | B10: Cliente activo | C10: Ahora imagina que ya eres cliente de Marley Coffee. Pide lo mismo que la última vez. | D10: C09 (LM5) | E10: Usa «Repetir último pedido» | F10: Éxito, tiempo, clics | G10: ≥ 80 % | H10: Recorrido de diseño (no medida)
A11: T7 | B11: Ejecutiva | C11: Eres ejecutiva de Marley Coffee: ingresa al CRM con tu cuenta. Un cliente te está esperando en el chat. Atiéndelo y respóndele. | D11: R00 → R01 → R02 | E11: Toma la conversación y responde (o envía la propuesta sugerida) | F11: Éxito, tiempo, SEQ | G11: ≥ 80 %; ≤ 60 s | H11: Medida: P4
A12: T8 | B12: Ejecutiva | C12: Averigua cada cuánto compra el Hotel Mirador Andino y cuánto gasta en promedio. Dile la respuesta al moderador. | D12: R03 → R04 | E12: Responde frecuencia y ticket promedio | F12: Éxito, tiempo | G12: ≥ 80 % | H12: Recorrido de diseño (no medida)
A13: T9 | B13: Jefatura | C13: Eres jefatura: ingresa al CRM con tu cuenta. ¿Cuántos clientes están comprando y cuántos SQL hay? ¿Qué zona trae más MQL? Dile la respuesta al moderador. | D13: R00 → R05 / R06 | E13: Responde los tres datos | F13: Éxito, tiempo, SEQ | G13: ≥ 80 %; ≤ 45 s | H13: Medida: P5
A15: Severidad (Nielsen 1994 [22]): 0 no es problema · 1 cosmético · 2 menor · 3 mayor · 4 catástrofe (corregir antes de lanzar). Se califica por frecuencia, impacto y persistencia.
A17: Guion de moderación (25 a 40 min)
A18: 0. Participantes y equipos | C18: Ronda 1 (15-10-2026): P1 computador, P2 y P3 celular en el sitio (T1); P4 computador (T7) y P5 celular (T9) en el CRM. El perfil se elige al empezar y la tarea se cuenta con las palabras de su negocio. Moderador con la guía Guia_Test_Usabilidad.html y el servidor del kit (Iniciar_test.bat): sin el servidor solo queda el PDF (así pasó en la ronda 1).
A19: 1. Bienvenida (2 min) | C19: «Gracias por ayudarnos. Vamos a probar un sitio en construcción, no a ti: no hay respuestas correctas. Piensa en voz alta: cuéntanos qué miras, qué esperas y qué te confunde. Te grabaremos solo con tu permiso.» Firmar consentimiento (Instrumentos_Terreno/E_CONSENTIMIENTO).
A20: 2. Contexto (3 min) | C20: ¿Qué tipo de negocio tienes o administras? ¿Cómo compran hoy el café y cómo lo reponen? ¿Con quién hablan cuando necesitan algo del proveedor?
A21: 3. Tarea (5 a 10 min) | C21: Una tarea por persona. El prototipo la muestra tal cual (columna C) y mide el tiempo por etapa, los toques y los toques sin respuesta. No mostrar dónde tocar. Si pasan 2 minutos sin avance o pide ayuda, ofrecer una pista y marcar éxito 0,5. Al terminar pregunta el SEQ (1 a 7). El informe PDF trae los tiempos por etapa y el mapa de calor; los CSV van a 08_TEST_REGISTRO.
A22: 4. Cierre (5 min) | C22: Cuestionario SUS (09_SUS). Preguntas: ¿Qué fue lo más útil? ¿Qué te hizo dudar? ¿Preferirías chat, llamada o correo, y por qué? ¿Qué te faltó para decidir?
A23: 5. Después de la sesión | C23: Pasar cada fricción a 10_HALLAZGOS con frecuencia, impacto, persistencia y severidad 0–4. Separar cita textual, observación e interpretación. No completar con supuestos lo que no se observó.
A24: Equipo comercial (T7–T9) | C24: Con P1 en computador: abrir test_crm.html y seguir T7 a T9 igual. Preguntar al final: ¿qué dato te falta para atender mejor?
A25: Lead magnets | C25: Observar si el participante lee el recuadro «Lo que recibes» antes de cada paso (LM1 a LM5) y preguntar al final: ¿qué te hizo seguir? ¿Qué esperabas recibir? Registrar citas en 10_HALLAZGOS.

Sheet 08_TEST_REGISTRO
A1: Registro por participante y tarea · ronda 1 (15-10-2026)
A2: Éxito: 1 = sin ayuda · 0,5 = con ayuda · 0 = no logra. Tiempo en segundos. SEQ 1 (muy difícil) a 7 (muy fácil). Fuente: informes PDF del test integrado, 15-10-2026, 00:07 a 01:01. Participantes con código, sin nombres. En blanco = no registrado (sin el servidor del kit no se guardaron los CSV).
A4: Participante | B4: Perfil / rol | C4: Dispositivo | D4: Tarea | E4: Éxito (1 / 0,5 / 0) | F4: Tiempo (s) | G4: Pidió ayuda (1/0) | H4: SEQ (1–7) | I4: Toques | J4: Toques sin respuesta | K4: Primera acción (s) | L4: Hasta Empresas (s) | M4: Pausa más larga (s) | N4: Pantalla con más tiempo | O4: SUS | P4: Nota del moderador (resumen)
A5: P1 | B5: Cliente · Hotel | C5: Computador | D5: T1 | E5: 0.5 | F5: 230.6 | G5: 1 | H5: 5 | I5: 29 | J5: 0 | K5: 10.2 | L5: 10.2 | M5: 21.4 | N5: C03 (47,6 s) | O5: 60 | P5: Le gustó el sitio y cómo interactuaban los videos. Se perdió después del formulario y del primer cuestionario: quería elegir la modalidad antes de que le dieran la propuesta.
A6: P2 | B6: Cliente · Restaurante | C6: Celular | D6: T1 | E6: 0.5 | F6: 196.2 | G6: 1 | H6: 6 | I6: 31 | J6: 2 | K6: 12.2 | L6: 15.5 | M6: 15.5 | N6: C03 (44,4 s) | O6: 60 | P6: No encontraba el menú (necesitó ayuda). Al pasar de pantalla en celular la vista no subía. Al terminar no supo qué hacer: faltó un aviso de que llegaría la propuesta. Preguntas largas; «faltaba un botón que seleccionara todo». 3 escenas en la portada eran muchas.
A7: P3 | B7: Cliente · Cafetería | C7: Celular | D7: T1 | E7: 1 | F7: 186.5 | G7: 0 | H7: 6 | I7: 31 | J7: 3 | K7: 6.7 | L7: 9.3 | M7: 17.1 | N7: C07 (57,3 s) | O7: 65 | P7: No encontraba el menú. Pulsó la solución arriba y le hubiese gustado ver antes los productos. Pidió el +56 9 ya escrito. Esperar la «nueva propuesta» al ajustar le pareció una pérdida de tiempo. Los precios se notaban poco; los videos le dieron seguridad.
A8: P4 | B8: Equipo · Ventas | C8: Computador | D8: T7 | E8: 0 | F8: 127.5 | G8: 0 | H8: 2 | I8: 18 | J8: 9 | K8: 7.1 | M8: 7.5 | N8: R02 (74,4 s) | O8: 27.5 | P8: Encontró el CRM intuitivo, pero no pudo dar una solución: no veía lo que cotizó el cliente ni una propuesta sugerida. Botones sin jerarquía; chat demasiado pequeño; pidió un mini tutorial.
A9: P5 | B9: Equipo · Jefatura | C9: Celular | D9: T9 | E9: 1 | F9: 76 | G9: 0 | H9: 5 | I9: 15 | J9: 10 | K9: 2.7 | M9: 10.1 | N9: R05 (52 s) | O9: 52.5 | P9: El panel le pareció útil, pero sin funciones para interactuar, cruzar datos o ver detalle. Su usuario escrito no entró. Todas las tarjetas e indicadores tenían el mismo color, sin jerarquía.
A10: P6 | P10: Ronda 2 (completar)
A11: P7 | P11: Ronda 2 (completar)
A12: P8 | P12: Ronda 2 (completar)
A14: Tarea | B14: Perfil | C14: Intentos | D14: Éxito sin ayuda (%) | E14: Éxito total (%) | F14: Tiempo promedio (s) | G14: SEQ promedio | H14: Umbral de éxito | I14: ¿Cumple?
A15: T1 | B15: Clientes (sitio) | C15: =COUNTIFS($D$5:$D$12,A15,$E$5:$E$12,"<>") | D15: =IFERROR(COUNTIFS($D$5:$D$12,A15,$E$5:$E$12,1)/C15,"pendiente") | E15: =IFERROR(AVERAGEIFS($E$5:$E$12,$D$5:$D$12,A15),"pendiente") | F15: =IFERROR(AVERAGEIFS($F$5:$F$12,$D$5:$D$12,A15),"pendiente") | G15: =IFERROR(AVERAGEIFS($H$5:$H$12,$D$5:$D$12,A15),"pendiente") | H15: 0.8 | I15: =IF(C15=0,"pendiente",IF(D15>=H15,"Sí","No"))
A16: T7 | B16: Ventas (CRM) | C16: =COUNTIFS($D$5:$D$12,A16,$E$5:$E$12,"<>") | D16: =IFERROR(COUNTIFS($D$5:$D$12,A16,$E$5:$E$12,1)/C16,"pendiente") | E16: =IFERROR(AVERAGEIFS($E$5:$E$12,$D$5:$D$12,A16),"pendiente") | F16: =IFERROR(AVERAGEIFS($F$5:$F$12,$D$5:$D$12,A16),"pendiente") | G16: =IFERROR(AVERAGEIFS($H$5:$H$12,$D$5:$D$12,A16),"pendiente") | H16: 0.8 | I16: =IF(C16=0,"pendiente",IF(D16>=H16,"Sí","No"))
A17: T9 | B17: Jefatura (CRM) | C17: =COUNTIFS($D$5:$D$12,A17,$E$5:$E$12,"<>") | D17: =IFERROR(COUNTIFS($D$5:$D$12,A17,$E$5:$E$12,1)/C17,"pendiente") | E17: =IFERROR(AVERAGEIFS($E$5:$E$12,$D$5:$D$12,A17),"pendiente") | F17: =IFERROR(AVERAGEIFS($F$5:$F$12,$D$5:$D$12,A17),"pendiente") | G17: =IFERROR(AVERAGEIFS($H$5:$H$12,$D$5:$D$12,A17),"pendiente") | H17: 0.8 | I17: =IF(C17=0,"pendiente",IF(D17>=H17,"Sí","No"))
A19: Nota de lectura: son 5 personas y una tarea larga cada una; los números orientan, no son estadística. Lo que pesa es lo que se repite entre personas y coincide con su línea de tiempo. Severidad y cambios en las hojas 10 y 22.

Sheet 09_SUS
A1: System Usability Scale (SUS) · ronda 1 y ronda 2
A2: Puntaje SUS 0–100 registrado por el test integrado (misma fórmula de abajo) el 15-10-2026; promedio de referencia 68 (Sauro 2011 [24]). Las respuestas por ítem de la ronda 1 no se guardaron (test sin el servidor del kit): solo se informa el puntaje del PDF.
A4: Participante | B4: Perfil | C4: Dispositivo | D4: SUS (0–100) | E4: Lectura
A5: P1 | B5: Cliente · Hotel | C5: Computador | D5: 60 | E5: =IF(D5>=68,"Sobre el promedio de referencia","Bajo el promedio de referencia (68)")
A6: P2 | B6: Cliente · Restaurante | C6: Celular | D6: 60 | E6: =IF(D6>=68,"Sobre el promedio de referencia","Bajo el promedio de referencia (68)")
A7: P3 | B7: Cliente · Cafetería | C7: Celular | D7: 65 | E7: =IF(D7>=68,"Sobre el promedio de referencia","Bajo el promedio de referencia (68)")
A8: P4 | B8: Equipo · Ventas | C8: Computador | D8: 27.5 | E8: =IF(D8>=68,"Sobre el promedio de referencia","Bajo el promedio de referencia (68)")
A9: P5 | B9: Equipo · Jefatura | C9: Celular | D9: 52.5 | E9: =IF(D9>=68,"Sobre el promedio de referencia","Bajo el promedio de referencia (68)")
A10: Promedio | B10: Clientes (P1–P3) | D10: =AVERAGE(D5:D7) | E10: =IF(D10>=68,"Cumple (≥ 68)","No cumple (< 68)")
A11: Promedio | B11: Equipo (P4–P5) | D11: =AVERAGE(D8:D9) | E11: =IF(D11>=68,"Cumple (≥ 68)","No cumple (< 68)")
A13: Ronda 2 · respuestas por ítem (1 = muy en desacuerdo a 5 = muy de acuerdo). Puntaje = ((ítems impares − 1) + (5 − ítems pares)) × 2,5
A14: Participante | B14: Í1 | C14: Í2 | D14: Í3 | E14: Í4 | F14: Í5 | G14: Í6 | H14: Í7 | I14: Í8 | J14: Í9 | K14: Í10 | L14: SUS
A15: P6 | L15: =IF(COUNT(B15:K15)=10,((B15-1)+(5-C15)+(D15-1)+(5-E15)+(F15-1)+(5-G15)+(H15-1)+(5-I15)+(J15-1)+(5-K15))*2.5,"")
A16: P7 | L16: =IF(COUNT(B16:K16)=10,((B16-1)+(5-C16)+(D16-1)+(5-E16)+(F16-1)+(5-G16)+(H16-1)+(5-I16)+(J16-1)+(5-K16))*2.5,"")
A17: P8 | L17: =IF(COUNT(B17:K17)=10,((B17-1)+(5-C17)+(D17-1)+(5-E17)+(F17-1)+(5-G17)+(H17-1)+(5-I17)+(J17-1)+(5-K17))*2.5,"")
A19: N.º | B19: Ítem del cuestionario
A20: 1 | B20: Creo que me gustaría usar este sitio con frecuencia.
A21: 2 | B21: Encontré el sitio innecesariamente complejo.
A22: 3 | B22: Pensé que era fácil de usar.
A23: 4 | B23: Creo que necesitaría ayuda de una persona con conocimientos técnicos para usarlo.
A24: 5 | B24: Las funciones del sitio estaban bien integradas.
A25: 6 | B25: Pensé que había demasiada inconsistencia.
A26: 7 | B26: Imagino que la mayoría aprendería a usarlo muy rápido.
A27: 8 | B27: Lo encontré muy engorroso de usar.
A28: 9 | B28: Me sentí muy confiado al usarlo.
A29: 10 | B29: Necesité aprender muchas cosas antes de poder usarlo.

Sheet 10_HALLAZGOS
A1: Hallazgos, severidad y mejoras
A2: Ciclo 0: revisión interna del autor del proyecto (09 a 12-10-2026), registrada con citas; NO es un test con usuarios. Ciclo 1: test con 5 usuarios del 15-10-2026 (participantes con código), con la mejora aplicada en v6. Severidad: crítica = 4, alta = 3, media = 2 (Nielsen 1994 [22]).
A4: ID | B4: Ciclo | C4: Fecha | D4: Fuente de evidencia | E4: Pantalla / tarea | F4: Hallazgo (fricción) | G4: Evidencia (cita u observación) | H4: Frecuencia | I4: Impacto | J4: Persistencia | K4: Severidad (0–4) | L4: Mejora incorporada | M4: Versión | N4: Estado
A5: H01 | B5: 0 | C5: 10-10-2026 | D5: Revisión interna (autor) | E5: C07–C10 | F5: Tras las 4 preguntas venían varias etapas (recomendación, propuesta, solicitud) que se leían como pestañas | G5: «después de las cuatro preguntas vienen hartas fases, como pestañas, que siento que son más fricciones» | H5: Alta | I5: Alto | J5: Alta | K5: 3 | L5: Contacto humano inmediato después de las preguntas (C05); lo demás pasa al portal | M5: v4 | N5: Incorporado; re-test con usuarios pendiente (T3)
A6: H02 | B6: 0 | C6: 10-10-2026 | D6: Revisión interna (autor) | E6: C05–C06 | F6: No se podía elegir hablar con una persona por chat real, llamada o correo | G6: Pidió llamada, correo o chat real en el portal, con un bot de bienvenida y espera según disponibilidad | H6: Alta | I6: Alto | J6: Alta | K6: 3 | L6: Omnicanal: chat real con bot y espera, llamada en cola o agendada, correo; cambio de canal sin perder la conversación | M6: v4 | N6: Incorporado; re-test pendiente (T3, T4)
A7: H03 | B7: 0 | C7: 10-10-2026 | D7: Revisión interna (autor) | E7: C04, CRM | F7: La geografía no pesaba en el puntaje ni en la asignación de ejecutiva | G7: «no es lo mismo un hotel o restaurante en las condes o providencia que en santiago centro» | H7: Alta | I7: Medio | J7: Alta | K7: 2 | L7: Comuna como pregunta 2; evento 14 en Engagement; 15 % en Financial; ejecutiva y ruta por zona; mapa R06 | M7: v4 | N7: Incorporado; calibrar con ventas por comuna
A8: H04 | B8: 0 | C8: 10-10-2026 | D8: Revisión interna (autor) | E8: CRM | F8: Menú del CRM demasiado largo (12 secciones) y centrado en el puntaje | G8: «tiene un menú gigante… ni yo mismo lo podría ocupar» | H8: Alta | I8: Alto | J8: Alta | K8: 3 | L8: Menú de 6 secciones por rol; puntaje como apoyo | M8: v4 | N8: Incorporado; re-test pendiente (T7–T9)
A9: H05 | B9: 0 | C9: 10-10-2026 | D9: Revisión interna (autor) | E9: R04 | F9: La ficha no mostraba qué compra el cliente ni con qué frecuencia | G9: Pidió ver qué compra, cuántas veces, primera compra, frecuencia y ticket promedio | H9: Alta | I9: Alto | J9: Alta | K9: 3 | L9: Ficha con datos de compra al frente y próxima mejor acción | M9: v4 | N9: Incorporado; re-test pendiente (T8)
A10: H06 | B10: 0 | C10: 10-10-2026 | D10: Revisión interna (autor) | E10: R05 | F10: El panel de jefatura no era agregado | G10: Pidió ver cuántos compran, MQL y SQL actuales y referidos, no a cada persona | H10: Media | I10: Medio | J10: Alta | K10: 2 | L10: Panel agregado por tipo de cliente y por zona, sin ranking por persona | M10: v4 | N10: Incorporado; re-test pendiente (T9)
A11: H07 | B11: 0 | C11: 10-10-2026 | D11: Revisión interna (autor) | E11: C02, C06, C08 | F11: Videos de casos con logos incorrectos, tazas sin marca y fuera del flujo | G11: «si en verdad vemos un video y no sale la marca bien… se ve como una inconsistencia» | H11: Alta | I11: Alto | J11: Alta | K11: 3 | L11: 2 videos nuevos desde fotos oficiales, revisados cuadro a cuadro, en C02, C06 y C08 de los 3 entregables | M11: v4 | N11: Incorporado
A12: H08 | B12: 0 | C12: 09-10-2026 | D12: Revisión interna (autor) | E12: Todo el sitio | F12: La marca aparecía como «Marley» sola | G12: «si pones solo marley, se puede mal entender. la marca es marley coffee» | H12: Media | I12: Medio | J12: Alta | K12: 2 | L12: Regla de marca en textos, etiquetas e informe; verificación automática | M12: v4 | N12: Incorporado; verificado 0 casos
A13: H09 | B13: 0 | C13: 09-10-2026 | D13: Revisión interna (autor) | E13: CRM | F13: El CRM se veía vacío en wireframes y mockups | G13: «sobre todo el crm que no había nada» | H13: Alta | I13: Alto | J13: Alta | K13: 3 | L13: Caso de ejemplo y datos de demostración rotulados en los tres entregables | M13: v3→v4 | N13: Incorporado
A14: H10 | B14: 0 | C14: 08-10-2026 | D14: Revisión interna (autor) | E14: Estados | F14: Estados en inglés incomprensibles («pending…») | G14: Vio una frase «pending…» que no entendía | H14: Media | I14: Medio | J14: Media | K14: 2 | L14: Todos los estados en español; verificación automática sin palabras en inglés | M14: v3→v4 | N14: Incorporado; verificado 0 casos
